#VRML_SIM R2023b utf8

EXTERNPROTO "https://raw.githubusercontent.com/cyberbotics/webots/R2023b/projects/objects/backgrounds/protos/TexturedBackground.proto"
EXTERNPROTO "https://raw.githubusercontent.com/cyberbotics/webots/R2023b/projects/objects/backgrounds/protos/TexturedBackgroundLight.proto"
EXTERNPROTO "https://raw.githubusercontent.com/cyberbotics/webots/R2023b/projects/objects/floors/protos/RectangleArena.proto"
EXTERNPROTO "https://raw.githubusercontent.com/cyberbotics/webots/R2023b/projects/appearances/protos/GalvanizedMetal.proto"
EXTERNPROTO "https://raw.githubusercontent.com/cyberbotics/webots/R2023b/projects/appearances/protos/Rubber.proto"

WorldInfo {
}
Viewpoint {
  orientation -0.32430118973700695 0.47029880355430664 0.8207604849836214 1.2633562478090212
  position -0.6541257634982185 -8.37975267657988 5.847677930530779
}
TexturedBackground {
}
TexturedBackgroundLight {
}
RectangleArena {
  floorSize 50 50
  floorTileSize 5 5
}
Robot {
  translation 2.02064 -3.0348 0.15
  children [
    HingeJoint {
      jointParameters HingeJointParameters {
        axis 0 1 0
        anchor 0.3 0.15 0
      }
      device [
        RotationalMotor {
          name "wheel1"
          acceleration 10
          maxTorque 100
        }
        PositionSensor {
        }
      ]
      endPoint Solid {
        translation 0.3 0.200013 6.253759999974957e-06
        rotation -0.9999999999998703 3.601716101736719e-07 3.6005724599886707e-07 4.712071375380367
        children [
          DEF Wheel Shape {
            appearance Rubber {
            }
            geometry Cylinder {
              height 0.1
              radius 0.15
            }
          }
        ]
        name "wheel1"
        boundingObject USE Wheel
        physics Physics {
          density -1
          mass 0.5
        }
      }
    }
    HingeJoint {
      jointParameters HingeJointParameters {
        axis 0 1 0
        anchor 0.3 -0.15 0
      }
      device [
        RotationalMotor {
          name "wheel2"
          acceleration 10
          maxTorque 100
        }
        PositionSensor {
        }
      ]
      endPoint Solid {
        translation 0.3 -0.20002799999999998 6.253769999999772e-06
        rotation -0.9999999999998701 -3.6027964529186784e-07 -3.6040325985937447e-07 4.712732064457683
        children [
          USE Wheel
        ]
        name "wheel2"
        boundingObject USE Wheel
        physics Physics {
          density -1
          mass 0.5
        }
      }
    }
    HingeJoint {
      jointParameters HingeJointParameters {
        axis 0 1 0
        anchor -0.3 0.15 0
      }
      device [
        RotationalMotor {
          name "wheel3"
          acceleration 10
          maxTorque 100
        }
        PositionSensor {
        }
      ]
      endPoint Solid {
        translation -0.3 0.2 6.253750000055739e-06
        rotation -0.9999999999998702 3.6007795436994685e-07 3.603647096269362e-07 4.713184995270961
        children [
          USE Wheel
        ]
        name "wheel3"
        boundingObject USE Wheel
        physics Physics {
          density -1
          mass 0.5
        }
      }
    }
    HingeJoint {
      jointParameters HingeJointParameters {
        axis 0 1 0
        anchor -0.3 -0.15 0
      }
      device [
        RotationalMotor {
          name "wheel4"
          acceleration 10
          maxTorque 100
        }
        PositionSensor {
        }
      ]
      endPoint Solid {
        translation -0.3 -0.200013 6.253760000031631e-06
        rotation -0.9999999999998701 -3.601716346272191e-07 -3.604586634357764e-07 4.7131856191674775
        children [
          USE Wheel
        ]
        name "wheel4"
        boundingObject USE Wheel
        physics Physics {
          density -1
          mass 0.5
        }
      }
    }
    DEF Hull Shape {
      appearance GalvanizedMetal {
      }
      geometry Box {
        size 1 0.3 0.15
      }
    }
  ]
  name "robot_simple"
  boundingObject USE Hull
  physics Physics {
    density -1
    mass 1
  }
  controller "SimpleVechicle"
}
